Workbook

Sheet README
A1: Item | B1: Definition
A2: Scope | B2: Supplementary full paired rerun; original submitted-paper aggregates remain unchanged.
A3: Population | B3: 1858 failed generation attempts; 566 generation-run/function units.
A4: Model | B4: gemini-2.5-flash-nothinking; provider alias gemini-2.5-flash; same gateway and API account for both methods.
A5: Gateway | B5: https://4sapi.org (OpenAI chat/completions for RuTeR; Anthropic messages for Claude Code).
A6: Claude Code | B6: 2.1.281; max 20 turns; case timeout 900s; Cargo timeout 600s; two isolated workers in the full run.
A7: RuTeR | B7: topk=3; max three LLM rounds per unresolved function; case timeout 900s; LLM timeout 120s.
A8: Tokens | B8: Provider input + output for all requests in the final valid trial, including ordinary failures and valid rule-only zero-token cases.
A9: Cache | B9: Claude primary cost is billing_usage.openai_usage.total_tokens; do not add cache-read counts again.
A10: Strict success | B10: RuTeR: passing patch verification, zero errors/unresolved test functions. Claude: passing final compile, zero errors, scope/integrity guards; not semantic equivalence.
A11: Function grouping | B11: function_id is a pseudonym for (generation run_id, node_id). Different runs remain distinct.
A12: Salvage | B12: A function is salvaged iff at least one of its failed generation attempts has an eligible strict repair.
... A19: Rerunning | B19: Raw failed tests and clean crate snapshots are separate inputs, not reconstructed by this compact workbook. See experiments/CLAUDE_CODE_EXPERIMENT.md.

Sheet Summary
A1: method | B1: budget_multiple | C1: attempts | D1: repaired | E1: repair_rate | F1: function_units | G1: salvaged | H1: salvage_rate | I1: mean_full_run_tokens | J1: full_run_token_ratio | K1: token_cap
A2: RuTeR | C2: 1858 | D2: 872 | E2: 0.46932185 | F2: 566 | G2: 375 | H2: 0.66254417 | I2: 4662.9047 | J2: 1
A3: Claude Code | B3: 5 | C3: 1858 | D3: 251 | E3: 0.1350915 | F3: 566 | G3: 171 | H3: 0.30212014 | I3: 117410.81 | J3: 25.179757 | K3: 23314.524
A4: Claude Code | B4: 10 | C4: 1858 | D4: 600 | E4: 0.32292788 | F4: 566 | G4: 320 | H4: 0.56537102 | I4: 117410.81 | J4: 25.179757 | K4: 46629.047
A5: Claude Code | C5: 1858 | D5: 1297 | E5: 0.69806243 | F5: 566 | G5: 495 | H5: 0.8745583 | I5: 117410.81 | J5: 25.179757

Sheet Calculations
A1: Metric | B1: Value
A2: Attempts | B2: =COUNTA(Cases!A2:A1859) -> 1858
A3: Functions | B3: =COUNTA(Functions!A2:A567) -> 566
A4: RuTeR total tokens | B4: =SUM(Cases!J2:J1859) -> 8663677
A5: Claude total tokens | B5: =SUM(Cases!O2:O1859) -> 218149284
A6: RuTeR mean tokens | B6: =B4/B2 -> 4662.9047
A7: Claude mean tokens | B7: =B5/B2 -> 117410.81
A8: Claude/RuTeR ratio | B8: =B5/B4 -> 25.179757
A10: First budget multiplier | B10: 5
A11: Second budget multiplier | B11: 10
A12: First exact token cap | B12: =B10*B6 -> 23314.524
A13: Second exact token cap | B13: =B11*B6 -> 46629.047
A14: RuTeR repairs | B14: =SUM(Cases!G2:G1859) -> 872
A15: First-budget Claude repairs | B15: =SUM(Cases!Q2:Q1859) -> 251
A16: Second-budget Claude repairs | B16: =SUM(Cases!R2:R1859) -> 600
A17: Unlimited Claude repairs | B17: =SUM(Cases!L2:L1859) -> 1297
A18: RuTeR repair rate | B18: =B14/B2 -> 0.46932185
A19: First-budget Claude repair rate | B19: =B15/B2 -> 0.1350915
A20: Second-budget Claude repair rate | B20: =B16/B2 -> 0.32292788
A21: Unlimited Claude repair rate | B21: =B17/B2 -> 0.69806243
A22: RuTeR salvaged | B22: =SUM(Functions!F2:F567) -> 375
A23: First-budget Claude salvaged | B23: =SUM(Functions!H2:H567) -> 171
A24: Second-budget Claude salvaged | B24: =SUM(Functions!I2:I567) -> 320
A25: Unlimited Claude salvaged | B25: =SUM(Functions!G2:G567) -> 495
A26: RuTeR salvage rate | B26: =B22/B3 -> 0.66254417
A27: First-budget Claude salvage rate | B27: =B23/B3 -> 0.30212014
A28: Second-budget Claude salvage rate | B28: =B24/B3 -> 0.56537102
A29: Unlimited Claude salvage rate | B29: =B25/B3 -> 0.8745583

Sheet Cases
A1: case_id | B1: function_id | C1: run_id | D1: crate | E1: generation_model | F1: error_codes | G1: ruter_success | H1: ruter_input_tokens | I1: ruter_output_tokens | J1: ruter_total_tokens | K1: ruter_requests | L1: claude_success | M1: claude_input_tokens | N1: claude_output_tokens | O1: claude_total_tokens | P1: claude_requests | Q1: claude_success_5x | R1: claude_success_10x
A2: case_0001 | B2: function_0001 | C2: run_001 | D2: humantime | E2: claude-3-5-haiku-20241022 | F2: E0433 | G2: 1 | H2: 0 | I2: 0 | J2: 0 | K2: 0 | L2: 1 | M2: 41707 | N2: 496 | O2: 42203 | P2: 5 | Q2: =IF(AND(L2=1,O2*Calculations!$B$2<=Calculations!$B$10*Calculations!$B$4),1,0) -> 0 | R2: =IF(AND(L2=1,O2*Calculations!$B$2<=Calculations!$B$11*Calculations!$B$4),1,0) -> 1
A3: case_0002 | B3: function_0001 | C3: run_001 | D3: humantime | E3: claude-3-5-haiku-20241022 | F3: E0433 | G3: 1 | H3: 0 | I3: 0 | J3: 0 | K3: 0 | L3: 1 | M3: 21308 | N3: 462 | O3: 21770 | P3: 3 | Q3: =IF(AND(L3=1,O3*Calculations!$B$2<=Calculations!$B$10*Calculations!$B$4),1,0) -> 1 | R3: =IF(AND(L3=1,O3*Calculations!$B$2<=Calculations!$B$11*Calculations!$B$4),1,0) -> 1
A4: case_0003 | B4: function_0001 | C4: run_001 | D4: humantime | E4: claude-3-5-haiku-20241022 | F4: E0433 | G4: 1 | H4: 0 | I4: 0 | J4: 0 | K4: 0 | L4: 1 | M4: 21254 | N4: 457 | O4: 21711 | P4: 3 | Q4: =IF(AND(L4=1,O4*Calculations!$B$2<=Calculations!$B$10*Calculations!$B$4),1,0) -> 1 | R4: =IF(AND(L4=1,O4*Calculations!$B$2<=Calculations!$B$11*Calculations!$B$4),1,0) -> 1
A5: case_0004 | B5: function_0002 | C5: run_001 | D5: humantime | E5: claude-3-5-haiku-20241022 | F5: E0433 | G5: 1 | H5: 0 | I5: 0 | J5: 0 | K5: 0 | L5: 1 | M5: 20144 | N5: 221 | O5: 20365 | P5: 3 | Q5: =IF(AND(L5=1,O5*Calculations!$B$2<=Calculations!$B$10*Calculations!$B$4),1,0) -> 1 | R5: =IF(AND(L5=1,O5*Calculations!$B$2<=Calculations!$B$11*Calculations!$B$4),1,0) -> 1
A6: case_0005 | B6: function_0002 | C6: run_001 | D6: humantime | E6: claude-3-5-haiku-20241022 | F6: E0433 | G6: 1 | H6: 0 | I6: 0 | J6: 0 | K6: 0 | L6: 1 | M6: 31450 | N6: 277 | O6: 31727 | P6: 4 | Q6: =IF(AND(L6=1,O6*Calculations!$B$2<=Calculations!$B$10*Calculations!$B$4),1,0) -> 0 | R6: =IF(AND(L6=1,O6*Calculations!$B$2<=Calculations!$B$11*Calculations!$B$4),1,0) -> 1
A7: case_0006 | B7: function_0002 | C7: run_001 | D7: humantime | E7: claude-3-5-haiku-20241022 | F7: E0433 | G7: 1 | H7: 0 | I7: 0 | J7: 0 | K7: 0 | L7: 1 | M7: 20148 | N7: 288 | O7: 20436 | P7: 3 | Q7: =IF(AND(L7=1,O7*Calculations!$B$2<=Calculations!$B$10*Calculations!$B$4),1,0) -> 1 | R7: =IF(AND(L7=1,O7*Calculations!$B$2<=Calculations!$B$11*Calculations!$B$4),1,0) -> 1
A8: case_0007 | B8: function_0003 | C8: run_001 | D8: humantime | E8: claude-3-5-haiku-20241022 | F8: E0433 | G8: 1 | H8: 0 | I8: 0 | J8: 0 | K8: 0 | L8: 1 | M8: 112586 | N8: 1528 | O8: 114114 | P8: 14 | Q8: =IF(AND(L8=1,O8*Calculations!$B$2<=Calculations!$B$10*Calculations!$B$4),1,0) -> 0 | R8: =IF(AND(L8=1,O8*Calculations!$B$2<=Calculations!$B$11*Calculations!$B$4),1,0) -> 0
A9: case_0008 | B9: function_0003 | C9: run_001 | D9: humantime | E9: claude-3-5-haiku-20241022 | F9: E0433 | G9: 1 | H9: 0 | I9: 0 | J9: 0 | K9: 0 | L9: 1 | M9: 37010 | N9: 581 | O9: 37591 | P9: 5 | Q9: =IF(AND(L9=1,O9*Calculations!$B$2<=Calculations!$B$10*Calculations!$B$4),1,0) -> 0 | R9: =IF(AND(L9=1,O9*Calculations!$B$2<=Calculations!$B$11*Calculations!$B$4),1,0) -> 1
A10: case_0009 | B10: function_0003 | C10: run_001 | D10: humantime | E10: claude-3-5-haiku-20241022 | F10: E0433 | G10: 1 | H10: 0 | I10: 0 | J10: 0 | K10: 0 | L10: 1 | M10: 66469 | N10: 1136 | O10: 67605 | P10: 8 | Q10: =IF(AND(L10=1,O10*Calculations!$B$2<=Calculations!$B$10*Calculations!$B$4),1,0) -> 0 | R10: =IF(AND(L10=1,O10*Calculations!$B$2<=Calculations!$B$11*Calculations!$B$4),1,0) -> 0
A11: case_0010 | B11: function_0003 | C11: run_001 | D11: humantime | E11: claude-3-5-haiku-20241022 | F11: E0433 | G11: 0 | H11: 4621 | I11: 156 | J11: 4777 | K11: 3 | L11: 1 | M11: 116436 | N11: 1121 | O11: 117557 | P11: 15 | Q11: =IF(AND(L11=1,O11*Calculations!$B$2<=Calculations!$B$10*Calculations!$B$4),1,0) -> 0 | R11: =IF(AND(L11=1,O11*Calculations!$B$2<=Calculations!$B$11*Calculations!$B$4),1,0) -> 0
A12: case_0011 | B12: function_0003 | C12: run_001 | D12: humantime | E12: claude-3-5-haiku-20241022 | F12: E0433 | G12: 0 | H12: 5179 | I12: 142 | J12: 5321 | K12: 3 | L12: 1 | M12: 159682 | N12: 1821 | O12: 161503 | P12: 19 | Q12: =IF(AND(L12=1,O12*Calculations!$B$2<=Calculations!$B$10*Calculations!$B$4),1,0) -> 0 | R12: =IF(AND(L12=1,O12*Calculations!$B$2<=Calculations!$B$11*Calculations!$B$4),1,0) -> 0
A13: case_0012 | B13: function_0003 | C13: run_001 | D13: humantime | E13: claude-3-5-haiku-20241022 | F13: E0433 | G13: 0 | H13: 4627 | I13: 165 | J13: 4792 | K13: 3 | L13: 0 | M13: 167865 | N13: 1247 | O13: 169112 | P13: 20 | Q13: =IF(AND(L13=1,O13*Calculations!$B$2<=Calculations!$B$10*Calculations!$B$4),1,0) -> 0 | R13: =IF(AND(L13=1,O13*Calculations!$B$2<=Calculations!$B$11*Calculations!$B$4),1,0) -> 0
... A407: case_0406 | B407: function_0072 | C407: run_005 | D407: humantime | E407: gpt-3.5-turbo | F407: E0432 | G407: 1 | H407: 0 | I407: 0 | J407: 0 | K407: 0 | L407: 1 | M407: 20214 | N407: 120 | O407: 20334 | P407: 3 | Q407: =IF(AND(L407=1,O407*Calculations!$B$2<=Calculations!$B$10*Calculations!$B$4),1,0) -> 1 | R407: =IF(AND(L407=1,O407*Calculations!$B$2<=Calculations!$B$11*Calculations!$B$4),1,0) -> 1
A408: case_0407 | B408: function_0073 | C408: run_005 | D408: humantime | E408: gpt-3.5-turbo | G408: 0 | H408: 0 | I408: 0 | J408: 0 | K408: 0 | L408: 1 | M408: 54422 | N408: 1706 | O408: 56128 | P408: 7 | Q408: =IF(AND(L408=1,O408*Calculations!$B$2<=Calculations!$B$10*Calculations!$B$4),1,0) -> 0 | R408: =IF(AND(L408=1,O408*Calculations!$B$2<=Calculations!$B$11*Calculations!$B$4),1,0) -> 0
A409: case_0408 | B409: function_0073 | C409: run_005 | D409: humantime | E409: gpt-3.5-turbo | F409: E0063,E0308,E0433 | G409: 0 | H409: 5469 | I409: 189 | J409: 5658 | K409: 3 | L409: 1 | M409: 70675 | N409: 1455 | O409: 72130 | P409: 9 | Q409: =IF(AND(L409=1,O409*Calculations!$B$2<=Calculations!$B$10*Calculations!$B$4),1,0) -> 0 | R409: =IF(AND(L409=1,O409*Calculations!$B$2<=Calculations!$B$11*Calculations!$B$4),1,0) -> 0
A410: case_0409 | B410: function_0073 | C410: run_005 | D410: humantime | E410: gpt-3.5-turbo | F410: E0063,E0308 | G410: 0 | H410: 5495 | I410: 222 | J410: 5717 | K410: 3 | L410: 1 | M410: 50749 | N410: 630 | O410: 51379 | P410: 7 | Q410: =IF(AND(L410=1,O410*Calculations!$B$2<=Calculations!$B$10*Calculations!$B$4),1,0) -> 0 | R410: =IF(AND(L410=1,O410*Calculations!$B$2<=Calculations!$B$11*Calculations!$B$4),1,0) -> 0
A411: case_0410 | B411: function_0073 | C411: run_005 | D411: humantime | E411: gpt-3.5-turbo | F411: E0063,E0308,E0433 | G411: 0 | H411: 5822 | I411: 216 | J411: 6038 | K411: 3 | L411: 1 | M411: 73787 | N411: 808 | O411: 74595 | P411: 7 | Q411: =IF(AND(L411=1,O411*Calculations!$B$2<=Calculations!$B$10*Calculations!$B$4),1,0) -> 0 | R411: =IF(AND(L411=1,O411*Calculations!$B$2<=Calculations!$B$11*Calculations!$B$4),1,0) -> 0
A412: case_0411 | B412: function_0073 | C412: run_005 | D412: humantime | E412: gpt-3.5-turbo | F412: E0063,E0308,E0433 | G412: 0 | H412: 5821 | I412: 307 | J412: 6128 | K412: 3 | L412: 1 | M412: 69999 | N412: 1241 | O412: 71240 | P412: 9 | Q412: =IF(AND(L412=1,O412*Calculations!$B$2<=Calculations!$B$10*Calculations!$B$4),1,0) -> 0 | R412: =IF(AND(L412=1,O412*Calculations!$B$2<=Calculations!$B$11*Calculations!$B$4),1,0) -> 0
A413: case_0412 | B413: function_0073 | C413: run_005 | D413: humantime | E413: gpt-3.5-turbo | F413: E0599 | G413: 1 | H413: 1780 | I413: 99 | J413: 1879 | K413: 1 | L413: 0 | M413: 28817 | N413: 834 | O413: 29651 | P413: 4 | Q413: =IF(AND(L413=1,O413*Calculations!$B$2<=Calculations!$B$10*Calculations!$B$4),1,0) -> 0 | R413: =IF(AND(L413=1,O413*Calculations!$B$2<=Calculations!$B$11*Calculations!$B$4),1,0) -> 0
A414: case_0413 | B414: function_0073 | C414: run_005 | D414: humantime | E414: gpt-3.5-turbo | F414: E0063,E0308,E0433 | G414: 0 | H414: 5688 | I414: 268 | J414: 5956 | K414: 3 | L414: 1 | M414: 35859 | N414: 1498 | O414: 37357 | P414: 5 | Q414: =IF(AND(L414=1,O414*Calculations!$B$2<=Calculations!$B$10*Calculations!$B$4),1,0) -> 0 | R414: =IF(AND(L414=1,O414*Calculations!$B$2<=Calculations!$B$11*Calculations!$B$4),1,0) -> 1
A415: case_0414 | B415: function_0073 | C415: run_005 | D415: humantime | E415: gpt-3.5-turbo | F415: E0063,E0308,E0433 | G415: 0 | H415: 5824 | I415: 237 | J415: 6061 | K415: 3 | L415: 1 | M415: 52740 | N415: 767 | O415: 53507 | P415: 6 | Q415: =IF(AND(L415=1,O415*Calculations!$B$2<=Calculations!$B$10*Calculations!$B$4),1,0) -> 0 | R415: =IF(AND(L415=1,O415*Calculations!$B$2<=Calculations!$B$11*Calculations!$B$4),1,0) -> 0
A416: case_0415 | B416: function_0073 | C416: run_005 | D416: humantime | E416: gpt-3.5-turbo | F416: E0063,E0308,E0432 | G416: 0 | H416: 7583 | I416: 234 | J416: 7817 | K416: 3 | L416: 1 | M416: 104372 | N416: 2162 | O416: 106534 | P416: 8 | Q416: =IF(AND(L416=1,O416*Calculations!$B$2<=Calculations!$B$10*Calculations!$B$4),1,0) -> 0 | R416: =IF(AND(L416=1,O416*Calculations!$B$2<=Calculations!$B$11*Calculations!$B$4),1,0) -> 0
A417: case_0416 | B417: function_0073 | C417: run_005 | D417: humantime | E417: gpt-3.5-turbo | F417: E0063,E0433 | G417: 0 | H417: 5423 | I417: 276 | J417: 5699 | K417: 3 | L417: 1 | M417: 113526 | N417: 1017 | O417: 114543 | P417: 12 | Q417: =IF(AND(L417=1,O417*Calculations!$B$2<=Calculations!$B$10*Calculations!$B$4),1,0) -> 0 | R417: =IF(AND(L417=1,O417*Calculations!$B$2<=Calculations!$B$11*Calculations!$B$4),1,0) -> 0
A418: case_0417 | B418: function_0073 | C418: run_005 | D418: humantime | E418: gpt-3.5-turbo | F418: E0063,E0308,E0433 | G418: 0 | H418: 5696 | I418: 268 | J418: 5964 | K418: 3 | L418: 1 | M418: 73480 | N418: 760 | O418: 74240 | P418: 7 | Q418: =IF(AND(L418=1,O418*Calculations!$B$2<=Calculations!$B$10*Calculations!$B$4),1,0) -> 0 | R418: =IF(AND(L418=1,O418*Calculations!$B$2<=Calculations!$B$11*Calculations!$B$4),1,0) -> 0
A419: case_0418 | B419: function_0073 | C419: run_005 | D419: humantime | E419: gpt-3.5-turbo | F419: E0063,E0308,E0433 | G419: 0 | H419: 5562 | I419: 200 | J419: 5762 | K419: 3 | L419: 1 | M419: 71419 | N419: 806 | O419: 72225 | P419: 6 | Q419: =IF(AND(L419=1,O419*Calculations!$B$2<=Calculations!$B$10*Calculations!$B$4),1,0) -> 0 | R419: =IF(AND(L419=1,O419*Calculations!$B$2<=Calculations!$B$11*Calculations!$B$4),1,0) -> 0
A420: case_0419 | B420: function_0074 | C420: run_005 | D420: humantime | E420: gpt-3.5-turbo | F420: E0063,E0425,E0433 | G420: 0 | H420: 5645 | I420: 273 | J420: 5918 | K420: 3 | L420: 1 | M420: 67593 | N420: 965 | O420: 68558 | P420: 5 | Q420: =IF(AND(L420=1,O420*Calculations!$B$2<=Calculations!$B$10*Calculations!$B$4),1,0) -> 0 | R420: =IF(AND(L420=1,O420*Calculations!$B$2<=Calculations!$B$11*Calculations!$B$4),1,0) -> 0
... A431: case_0430 | B431: function_0074 | C431: run_005 | D431: humantime | E431: gpt-3.5-turbo | F431: E0433,E0599 | G431: 0 | H431: 5812 | I431: 143 | J431: 5955 | K431: 3 | L431: 1 | M431: 97198 | N431: 1245 | O431: 98443 | P431: 12 | Q431: =IF(AND(L431=1,O431*Calculations!$B$2<=Calculations!$B$10*Calculations!$B$4),1,0) -> 0 | R431: =IF(AND(L431=1,O431*Calculations!$B$2<=Calculations!$B$11*Calculations!$B$4),1,0) -> 0
A432: case_0431 | B432: function_0075 | C432: run_005 | D432: humantime | E432: gpt-3.5-turbo | G432: 0 | H432: 0 | I432: 0 | J432: 0 | K432: 0 | L432: 1 | M432: 76361 | N432: 1266 | O432: 77627 | P432: 7 | Q432: =IF(AND(L432=1,O432*Calculations!$B$2<=Calculations!$B$10*Calculations!$B$4),1,0) -> 0 | R432: =IF(AND(L432=1,O432*Calculations!$B$2<=Calculations!$B$11*Calculations!$B$4),1,0) -> 0
A433: case_0432 | B433: function_0075 | C433: run_005 | D433: humantime | E433: gpt-3.5-turbo | F433: E0599 | G433: 0 | H433: 5615 | I433: 157 | J433: 5772 | K433: 3 | L433: 1 | M433: 27592 | N433: 477 | O433: 28069 | P433: 4 | Q433: =IF(AND(L433=1,O433*Calculations!$B$2<=Calculations!$B$10*Calculations!$B$4),1,0) -> 0 | R433: =IF(AND(L433=1,O433*Calculations!$B$2<=Calculations!$B$11*Calculations!$B$4),1,0) -> 1
A434: case_0433 | B434: function_0075 | C434: run_005 | D434: humantime | E434: gpt-3.5-turbo | F434: E0599 | G434: 1 | H434: 3705 | I434: 140 | J434: 3845 | K434: 2 | L434: 1 | M434: 45955 | N434: 655 | O434: 46610 | P434: 4 | Q434: =IF(AND(L434=1,O434*Calculations!$B$2<=Calculations!$B$10*Calculations!$B$4),1,0) -> 0 | R434: =IF(AND(L434=1,O434*Calculations!$B$2<=Calculations!$B$11*Calculations!$B$4),1,0) -> 1
A435: case_0434 | B435: function_0075 | C435: run_005 | D435: humantime | E435: gpt-3.5-turbo | F435: E0586 | G435: 0 | H435: 0 | I435: 0 | J435: 0 | K435: 0 | L435: 1 | M435: 52111 | N435: 936 | O435: 53047 | P435: 4 | Q435: =IF(AND(L435=1,O435*Calculations!$B$2<=Calculations!$B$10*Calculations!$B$4),1,0) -> 0 | R435: =IF(AND(L435=1,O435*Calculations!$B$2<=Calculations!$B$11*Calculations!$B$4),1,0) -> 0
A436: case_0435 | B436: function_0075 | C436: run_005 | D436: humantime | E436: gpt-3.5-turbo | F436: E0261,E0308,E0586 | G436: 0 | H436: 0 | I436: 0 | J436: 0 | K436: 0 | L436: 0 | M436: 86262 | N436: 1469 | O436: 87731 | P436: 8 | Q436: =IF(AND(L436=1,O436*Calculations!$B$2<=Calculations!$B$10*Calculations!$B$4),1,0) -> 0 | R436: =IF(AND(L436=1,O436*Calculations!$B$2<=Calculations!$B$11*Calculations!$B$4),1,0) -> 0
A437: case_0436 | B437: function_0075 | C437: run_005 | D437: humantime | E437: gpt-3.5-turbo | F437: E0261,E0433,E0586 | G437: 0 | H437: 0 | I437: 0 | J437: 0 | K437: 0 | L437: 0 | M437: 96384 | N437: 1192 | O437: 97576 | P437: 11 | Q437: =IF(AND(L437=1,O437*Calculations!$B$2<=Calculations!$B$10*Calculations!$B$4),1,0) -> 0 | R437: =IF(AND(L437=1,O437*Calculations!$B$2<=Calculations!$B$11*Calculations!$B$4),1,0) -> 0
A438: case_0437 | B438: function_0075 | C438: run_005 | D438: humantime | E438: gpt-3.5-turbo | F438: E0061,E0261,E0308,E0433 | G438: 0 | H438: 5881 | I438: 141 | J438: 6022 | K438: 3 | L438: 0 | M438: 121747 | N438: 2608 | O438: 124355 | P438: 15 | Q438: =IF(AND(L438=1,O438*Calculations!$B$2<=Calculations!$B$10*Calculations!$B$4),1,0) -> 0 | R438: =IF(AND(L438=1,O438*Calculations!$B$2<=Calculations!$B$11*Calculations!$B$4),1,0) -> 0
A439: case_0438 | B439: function_0075 | C439: run_005 | D439: humantime | E439: gpt-3.5-turbo | F439: E0432 | G439: 0 | H439: 7197 | I439: 267 | J439: 7464 | K439: 3 | L439: 1 | M439: 122304 | N439: 1129 | O439: 123433 | P439: 8 | Q439: =IF(AND(L439=1,O439*Calculations!$B$2<=Calculations!$B$10*Calculations!$B$4),1,0) -> 0 | R439: =IF(AND(L439=1,O439*Calculations!$B$2<=Calculations!$B$11*Calculations!$B$4),1,0) -> 0
A440: case_0439 | B440: function_0075 | C440: run_005 | D440: humantime | E440: gpt-3.5-turbo | G440: 0 | H440: 0 | I440: 0 | J440: 0 | K440: 0 | L440: 1 | M440: 65573 | N440: 1088 | O440: 66661 | P440: 9 | Q440: =IF(AND(L440=1,O440*Calculations!$B$2<=Calculations!$B$10*Calculations!$B$4),1,0) -> 0 | R440: =IF(AND(L440=1,O440*Calculations!$B$2<=Calculations!$B$11*Calculations!$B$4),1,0) -> 0
A441: case_0440 | B441: function_0075 | C441: run_005 | D441: humantime | E441: gpt-3.5-turbo | F441: E0599 | G441: 0 | H441: 5635 | I441: 162 | J441: 5797 | K441: 3 | L441: 1 | M441: 49721 | N441: 435 | O441: 50156 | P441: 4 | Q441: =IF(AND(L441=1,O441*Calculations!$B$2<=Calculations!$B$10*Calculations!$B$4),1,0) -> 0 | R441: =IF(AND(L441=1,O441*Calculations!$B$2<=Calculations!$B$11*Calculations!$B$4),1,0) -> 0
A442: case_0441 | B442: function_0075 | C442: run_005 | D442: humantime | E442: gpt-3.5-turbo | F442: E0433 | G442: 1 | H442: 2384 | I442: 106 | J442: 2490 | K442: 1 | L442: 1 | M442: 68680 | N442: 913 | O442: 69593 | P442: 9 | Q442: =IF(AND(L442=1,O442*Calculations!$B$2<=Calculations!$B$10*Calculations!$B$4),1,0) -> 0 | R442: =IF(AND(L442=1,O442*Calculations!$B$2<=Calculations!$B$11*Calculations!$B$4),1,0) -> 0
A443: case_0442 | B443: function_0075 | C443: run_005 | D443: humantime | E443: gpt-3.5-turbo | F443: E0063,E0433 | G443: 0 | H443: 5327 | I443: 216 | J443: 5543 | K443: 3 | L443: 1 | M443: 64753 | N443: 1117 | O443: 65870 | P443: 6 | Q443: =IF(AND(L443=1,O443*Calculations!$B$2<=Calculations!$B$10*Calculations!$B$4),1,0) -> 0 | R443: =IF(AND(L443=1,O443*Calculations!$B$2<=Calculations!$B$11*Calculations!$B$4),1,0) -> 0
...

Sheet Functions
A1: function_id | B1: run_id | C1: crate | D1: generation_model | E1: attempts | F1: ruter_salvaged | G1: claude_salvaged | H1: claude_salvaged_5x | I1: claude_salvaged_10x
A2: function_0001 | B2: run_001 | C2: humantime | D2: claude-3-5-haiku-20241022 | E2: =COUNTIF(Cases!$B$2:$B$1859,A2) -> 3 | F2: =IF(COUNTIFS(Cases!$B$2:$B$1859,A2,Cases!$G$2:$G$1859,1)>0,1,0) -> 1 | G2: =IF(COUNTIFS(Cases!$B$2:$B$1859,A2,Cases!$L$2:$L$1859,1)>0,1,0) -> 1 | H2: =IF(COUNTIFS(Cases!$B$2:$B$1859,A2,Cases!$Q$2:$Q$1859,1)>0,1,0) -> 1 | I2: =IF(COUNTIFS(Cases!$B$2:$B$1859,A2,Cases!$R$2:$R$1859,1)>0,1,0) -> 1
A3: function_0002 | B3: run_001 | C3: humantime | D3: claude-3-5-haiku-20241022 | E3: =COUNTIF(Cases!$B$2:$B$1859,A3) -> 3 | F3: =IF(COUNTIFS(Cases!$B$2:$B$1859,A3,Cases!$G$2:$G$1859,1)>0,1,0) -> 1 | G3: =IF(COUNTIFS(Cases!$B$2:$B$1859,A3,Cases!$L$2:$L$1859,1)>0,1,0) -> 1 | H3: =IF(COUNTIFS(Cases!$B$2:$B$1859,A3,Cases!$Q$2:$Q$1859,1)>0,1,0) -> 1 | I3: =IF(COUNTIFS(Cases!$B$2:$B$1859,A3,Cases!$R$2:$R$1859,1)>0,1,0) -> 1
A4: function_0003 | B4: run_001 | C4: humantime | D4: claude-3-5-haiku-20241022 | E4: =COUNTIF(Cases!$B$2:$B$1859,A4) -> 6 | F4: =IF(COUNTIFS(Cases!$B$2:$B$1859,A4,Cases!$G$2:$G$1859,1)>0,1,0) -> 1 | G4: =IF(COUNTIFS(Cases!$B$2:$B$1859,A4,Cases!$L$2:$L$1859,1)>0,1,0) -> 1 | H4: =IF(COUNTIFS(Cases!$B$2:$B$1859,A4,Cases!$Q$2:$Q$1859,1)>0,1,0) -> 0 | I4: =IF(COUNTIFS(Cases!$B$2:$B$1859,A4,Cases!$R$2:$R$1859,1)>0,1,0) -> 1
A5: function_0004 | B5: run_001 | C5: humantime | D5: claude-3-5-haiku-20241022 | E5: =COUNTIF(Cases!$B$2:$B$1859,A5) -> 6 | F5: =IF(COUNTIFS(Cases!$B$2:$B$1859,A5,Cases!$G$2:$G$1859,1)>0,1,0) -> 1 | G5: =IF(COUNTIFS(Cases!$B$2:$B$1859,A5,Cases!$L$2:$L$1859,1)>0,1,0) -> 1 | H5: =IF(COUNTIFS(Cases!$B$2:$B$1859,A5,Cases!$Q$2:$Q$1859,1)>0,1,0) -> 1 | I5: =IF(COUNTIFS(Cases!$B$2:$B$1859,A5,Cases!$R$2:$R$1859,1)>0,1,0) -> 1
A6: function_0005 | B6: run_001 | C6: humantime | D6: claude-3-5-haiku-20241022 | E6: =COUNTIF(Cases!$B$2:$B$1859,A6) -> 3 | F6: =IF(COUNTIFS(Cases!$B$2:$B$1859,A6,Cases!$G$2:$G$1859,1)>0,1,0) -> 1 | G6: =IF(COUNTIFS(Cases!$B$2:$B$1859,A6,Cases!$L$2:$L$1859,1)>0,1,0) -> 1 | H6: =IF(COUNTIFS(Cases!$B$2:$B$1859,A6,Cases!$Q$2:$Q$1859,1)>0,1,0) -> 1 | I6: =IF(COUNTIFS(Cases!$B$2:$B$1859,A6,Cases!$R$2:$R$1859,1)>0,1,0) -> 1
A7: function_0006 | B7: run_001 | C7: humantime | D7: claude-3-5-haiku-20241022 | E7: =COUNTIF(Cases!$B$2:$B$1859,A7) -> 3 | F7: =IF(COUNTIFS(Cases!$B$2:$B$1859,A7,Cases!$G$2:$G$1859,1)>0,1,0) -> 1 | G7: =IF(COUNTIFS(Cases!$B$2:$B$1859,A7,Cases!$L$2:$L$1859,1)>0,1,0) -> 1 | H7: =IF(COUNTIFS(Cases!$B$2:$B$1859,A7,Cases!$Q$2:$Q$1859,1)>0,1,0) -> 1 | I7: =IF(COUNTIFS(Cases!$B$2:$B$1859,A7,Cases!$R$2:$R$1859,1)>0,1,0) -> 1
A8: function_0007 | B8: run_001 | C8: humantime | D8: claude-3-5-haiku-20241022 | E8: =COUNTIF(Cases!$B$2:$B$1859,A8) -> 3 | F8: =IF(COUNTIFS(Cases!$B$2:$B$1859,A8,Cases!$G$2:$G$1859,1)>0,1,0) -> 1 | G8: =IF(COUNTIFS(Cases!$B$2:$B$1859,A8,Cases!$L$2:$L$1859,1)>0,1,0) -> 1 | H8: =IF(COUNTIFS(Cases!$B$2:$B$1859,A8,Cases!$Q$2:$Q$1859,1)>0,1,0) -> 1 | I8: =IF(COUNTIFS(Cases!$B$2:$B$1859,A8,Cases!$R$2:$R$1859,1)>0,1,0) -> 1
A9: function_0008 | B9: run_001 | C9: humantime | D9: claude-3-5-haiku-20241022 | E9: =COUNTIF(Cases!$B$2:$B$1859,A9) -> 6 | F9: =IF(COUNTIFS(Cases!$B$2:$B$1859,A9,Cases!$G$2:$G$1859,1)>0,1,0) -> 1 | G9: =IF(COUNTIFS(Cases!$B$2:$B$1859,A9,Cases!$L$2:$L$1859,1)>0,1,0) -> 1 | H9: =IF(COUNTIFS(Cases!$B$2:$B$1859,A9,Cases!$Q$2:$Q$1859,1)>0,1,0) -> 0 | I9: =IF(COUNTIFS(Cases!$B$2:$B$1859,A9,Cases!$R$2:$R$1859,1)>0,1,0) -> 1
A10: function_0009 | B10: run_001 | C10: humantime | D10: claude-3-5-haiku-20241022 | E10: =COUNTIF(Cases!$B$2:$B$1859,A10) -> 6 | F10: =IF(COUNTIFS(Cases!$B$2:$B$1859,A10,Cases!$G$2:$G$1859,1)>0,1,0) -> 1 | G10: =IF(COUNTIFS(Cases!$B$2:$B$1859,A10,Cases!$L$2:$L$1859,1)>0,1,0) -> 1 | H10: =IF(COUNTIFS(Cases!$B$2:$B$1859,A10,Cases!$Q$2:$Q$1859,1)>0,1,0) -> 1 | I10: =IF(COUNTIFS(Cases!$B$2:$B$1859,A10,Cases!$R$2:$R$1859,1)>0,1,0) -> 1
A11: function_0010 | B11: run_001 | C11: humantime | D11: claude-3-5-haiku-20241022 | E11: =COUNTIF(Cases!$B$2:$B$1859,A11) -> 3 | F11: =IF(COUNTIFS(Cases!$B$2:$B$1859,A11,Cases!$G$2:$G$1859,1)>0,1,0) -> 1 | G11: =IF(COUNTIFS(Cases!$B$2:$B$1859,A11,Cases!$L$2:$L$1859,1)>0,1,0) -> 1 | H11: =IF(COUNTIFS(Cases!$B$2:$B$1859,A11,Cases!$Q$2:$Q$1859,1)>0,1,0) -> 1 | I11: =IF(COUNTIFS(Cases!$B$2:$B$1859,A11,Cases!$R$2:$R$1859,1)>0,1,0) -> 1
A12: function_0011 | B12: run_001 | C12: humantime | D12: claude-3-5-haiku-20241022 | E12: =COUNTIF(Cases!$B$2:$B$1859,A12) -> 12 | F12: =IF(COUNTIFS(Cases!$B$2:$B$1859,A12,Cases!$G$2:$G$1859,1)>0,1,0) -> 1 | G12: =IF(COUNTIFS(Cases!$B$2:$B$1859,A12,Cases!$L$2:$L$1859,1)>0,1,0) -> 1 | H12: =IF(COUNTIFS(Cases!$B$2:$B$1859,A12,Cases!$Q$2:$Q$1859,1)>0,1,0) -> 0 | I12: =IF(COUNTIFS(Cases!$B$2:$B$1859,A12,Cases!$R$2:$R$1859,1)>0,1,0) -> 1
A13: function_0012 | B13: run_001 | C13: humantime | D13: claude-3-5-haiku-20241022 | E13: =COUNTIF(Cases!$B$2:$B$1859,A13) -> 6 | F13: =IF(COUNTIFS(Cases!$B$2:$B$1859,A13,Cases!$G$2:$G$1859,1)>0,1,0) -> 1 | G13: =IF(COUNTIFS(Cases!$B$2:$B$1859,A13,Cases!$L$2:$L$1859,1)>0,1,0) -> 1 | H13: =IF(COUNTIFS(Cases!$B$2:$B$1859,A13,Cases!$Q$2:$Q$1859,1)>0,1,0) -> 0 | I13: =IF(COUNTIFS(Cases!$B$2:$B$1859,A13,Cases!$R$2:$R$1859,1)>0,1,0) -> 0
... A567: function_0566 | B567: run_017 | C567: semver | D567: gemini-2.5-flash-nothinking | E567: =COUNTIF(Cases!$B$2:$B$1859,A567) -> 2 | F567: =IF(COUNTIFS(Cases!$B$2:$B$1859,A567,Cases!$G$2:$G$1859,1)>0,1,0) -> 0 | G567: =IF(COUNTIFS(Cases!$B$2:$B$1859,A567,Cases!$L$2:$L$1859,1)>0,1,0) -> 0 | H567: =IF(COUNTIFS(Cases!$B$2:$B$1859,A567,Cases!$Q$2:$Q$1859,1)>0,1,0) -> 0 | I567: =IF(COUNTIFS(Cases!$B$2:$B$1859,A567,Cases!$R$2:$R$1859,1)>0,1,0) -> 0
